[2024-07-30T10:29:22.552+0900] {local_task_job_runner.py:120} INFO - ::group::Pre task execution logs
[2024-07-30T10:29:22.563+0900] {taskinstance.py:2076} INFO - Dependencies all met for dep_context=non-requeueable deps ti=<TaskInstance: movie.get_data scheduled__2024-07-28T04:10:00+00:00 [queued]>
[2024-07-30T10:29:22.566+0900] {taskinstance.py:2076} INFO - Dependencies all met for dep_context=requeueable deps ti=<TaskInstance: movie.get_data scheduled__2024-07-28T04:10:00+00:00 [queued]>
[2024-07-30T10:29:22.566+0900] {taskinstance.py:2306} INFO - Starting attempt 6 of 6
[2024-07-30T10:29:22.572+0900] {taskinstance.py:2330} INFO - Executing <Task(PythonVirtualenvOperator): get_data> on 2024-07-28 04:10:00+00:00
[2024-07-30T10:29:22.575+0900] {standard_task_runner.py:64} INFO - Started process 4417 to run task
[2024-07-30T10:29:22.578+0900] {standard_task_runner.py:90} INFO - Running: ['airflow', 'tasks', 'run', 'movie', 'get_data', 'scheduled__2024-07-28T04:10:00+00:00', '--job-id', '624', '--raw', '--subdir', 'DAGS_FOLDER/movie.py', '--cfg-path', '/var/folders/qv/0knwm5h50ml0skpppwpbks_r0000gp/T/tmpfa7d9u42']
[2024-07-30T10:29:22.579+0900] {standard_task_runner.py:91} INFO - Job 624: Subtask get_data
[2024-07-30T10:29:22.639+0900] {task_command.py:426} INFO - Running <TaskInstance: movie.get_data scheduled__2024-07-28T04:10:00+00:00 [running]> on host jeongui-MacBookPro.local
[2024-07-30T10:29:22.658+0900] {taskinstance.py:2648} INFO - Exporting env vars: AIRFLOW_CTX_DAG_OWNER='airflow' AIRFLOW_CTX_DAG_ID='movie' AIRFLOW_CTX_TASK_ID='get_data' AIRFLOW_CTX_EXECUTION_DATE='2024-07-28T04:10:00+00:00' AIRFLOW_CTX_TRY_NUMBER='6' AIRFLOW_CTX_DAG_RUN_ID='scheduled__2024-07-28T04:10:00+00:00'
[2024-07-30T10:29:22.658+0900] {taskinstance.py:430} INFO - ::endgroup::
[2024-07-30T10:29:22.663+0900] {baseoperator.py:400} WARNING - PythonVirtualenvOperator.execute cannot be called outside TaskInstance!
[2024-07-30T10:29:22.663+0900] {process_utils.py:183} INFO - Executing cmd: /Users/DE32/.pyenv/versions/3.11.9/envs/note/bin/python -m virtualenv /var/folders/qv/0knwm5h50ml0skpppwpbks_r0000gp/T/venvg0_4ucjm --python=python
[2024-07-30T10:29:22.665+0900] {process_utils.py:187} INFO - Output:
[2024-07-30T10:29:22.843+0900] {process_utils.py:191} INFO - created virtual environment CPython3.11.9.final.0-64 in 119ms
[2024-07-30T10:29:22.844+0900] {process_utils.py:191} INFO -   creator CPython3Posix(dest=/private/var/folders/qv/0knwm5h50ml0skpppwpbks_r0000gp/T/venvg0_4ucjm, clear=False, no_vcs_ignore=False, global=False)
[2024-07-30T10:29:22.844+0900] {process_utils.py:191} INFO -   seeder FromAppData(download=False, pip=bundle, setuptools=bundle, wheel=bundle, via=copy, app_data_dir=/Users/DE32/Library/Application Support/virtualenv)
[2024-07-30T10:29:22.844+0900] {process_utils.py:191} INFO -     added seed packages: pip==24.1, setuptools==70.1.0, wheel==0.43.0
[2024-07-30T10:29:22.845+0900] {process_utils.py:191} INFO -   activators BashActivator,CShellActivator,FishActivator,NushellActivator,PowerShellActivator,PythonActivator
[2024-07-30T10:29:22.855+0900] {process_utils.py:183} INFO - Executing cmd: /var/folders/qv/0knwm5h50ml0skpppwpbks_r0000gp/T/venvg0_4ucjm/bin/pip install -r /var/folders/qv/0knwm5h50ml0skpppwpbks_r0000gp/T/venvg0_4ucjm/requirements.txt
[2024-07-30T10:29:22.857+0900] {process_utils.py:187} INFO - Output:
[2024-07-30T10:29:23.605+0900] {process_utils.py:191} INFO - Collecting git+https://github.com/Jeonghoon2/movie/tree/0.2/api (from -r /var/folders/qv/0knwm5h50ml0skpppwpbks_r0000gp/T/venvg0_4ucjm/requirements.txt (line 1))
[2024-07-30T10:29:23.606+0900] {process_utils.py:191} INFO -   Cloning https://github.com/Jeonghoon2/movie/tree/0.2/api to /private/var/folders/qv/0knwm5h50ml0skpppwpbks_r0000gp/T/pip-req-build-yvd9luxd
[2024-07-30T10:29:23.618+0900] {process_utils.py:191} INFO -   Running command git clone --filter=blob:none --quiet https://github.com/Jeonghoon2/movie/tree/0.2/api /private/var/folders/qv/0knwm5h50ml0skpppwpbks_r0000gp/T/pip-req-build-yvd9luxd
[2024-07-30T10:29:23.709+0900] {process_utils.py:191} INFO -   fatal: repository 'https://github.com/Jeonghoon2/movie/tree/0.2/api/' not found
[2024-07-30T10:29:23.713+0900] {process_utils.py:191} INFO -   error: subprocess-exited-with-error
[2024-07-30T10:29:23.714+0900] {process_utils.py:191} INFO - 
[2024-07-30T10:29:23.714+0900] {process_utils.py:191} INFO -   × git clone --filter=blob:none --quiet https://github.com/Jeonghoon2/movie/tree/0.2/api /private/var/folders/qv/0knwm5h50ml0skpppwpbks_r0000gp/T/pip-req-build-yvd9luxd did not run successfully.
[2024-07-30T10:29:23.714+0900] {process_utils.py:191} INFO -   │ exit code: 128
[2024-07-30T10:29:23.714+0900] {process_utils.py:191} INFO -   ╰─> See above for output.
[2024-07-30T10:29:23.715+0900] {process_utils.py:191} INFO - 
[2024-07-30T10:29:23.715+0900] {process_utils.py:191} INFO -   note: This error originates from a subprocess, and is likely not a problem with pip.
[2024-07-30T10:29:23.715+0900] {process_utils.py:191} INFO - error: subprocess-exited-with-error
[2024-07-30T10:29:23.715+0900] {process_utils.py:191} INFO - 
[2024-07-30T10:29:23.715+0900] {process_utils.py:191} INFO - × git clone --filter=blob:none --quiet https://github.com/Jeonghoon2/movie/tree/0.2/api /private/var/folders/qv/0knwm5h50ml0skpppwpbks_r0000gp/T/pip-req-build-yvd9luxd did not run successfully.
[2024-07-30T10:29:23.716+0900] {process_utils.py:191} INFO - │ exit code: 128
[2024-07-30T10:29:23.716+0900] {process_utils.py:191} INFO - ╰─> See above for output.
[2024-07-30T10:29:23.716+0900] {process_utils.py:191} INFO - 
[2024-07-30T10:29:23.716+0900] {process_utils.py:191} INFO - note: This error originates from a subprocess, and is likely not a problem with pip.
[2024-07-30T10:29:23.786+0900] {process_utils.py:191} INFO - 
[2024-07-30T10:29:23.786+0900] {process_utils.py:191} INFO - [notice] A new release of pip is available: 24.1 -> 24.2
[2024-07-30T10:29:23.786+0900] {process_utils.py:191} INFO - [notice] To update, run: python -m pip install --upgrade pip
[2024-07-30T10:29:23.875+0900] {taskinstance.py:441} INFO - ::group::Post task execution logs
[2024-07-30T10:29:23.875+0900] {taskinstance.py:2905} ERROR - Task failed with exception
Traceback (most recent call last):
  File "/Users/DE32/.pyenv/versions/3.11.9/envs/note/lib/python3.11/site-packages/airflow/models/taskinstance.py", line 465, in _execute_task
    result = _execute_callable(context=context, **execute_callable_kwargs)
             ^^^^^^^^^^^^^^^^^^^^^^^^^^^^^^^^^^^^^^^^^^^^^^^^^^^^^^^^^^^^^
  File "/Users/DE32/.pyenv/versions/3.11.9/envs/note/lib/python3.11/site-packages/airflow/models/taskinstance.py", line 432, in _execute_callable
    return execute_callable(context=context, **execute_callable_kwargs)
           ^^^^^^^^^^^^^^^^^^^^^^^^^^^^^^^^^^^^^^^^^^^^^^^^^^^^^^^^^^^^
  File "/Users/DE32/.pyenv/versions/3.11.9/envs/note/lib/python3.11/site-packages/airflow/models/baseoperator.py", line 401, in wrapper
    return func(self, *args, **kwargs)
           ^^^^^^^^^^^^^^^^^^^^^^^^^^^
  File "/Users/DE32/.pyenv/versions/3.11.9/envs/note/lib/python3.11/site-packages/airflow/operators/python.py", line 437, in execute
    return super().execute(context=serializable_context)
           ^^^^^^^^^^^^^^^^^^^^^^^^^^^^^^^^^^^^^^^^^^^^^
  File "/Users/DE32/.pyenv/versions/3.11.9/envs/note/lib/python3.11/site-packages/airflow/models/baseoperator.py", line 401, in wrapper
    return func(self, *args, **kwargs)
           ^^^^^^^^^^^^^^^^^^^^^^^^^^^
  File "/Users/DE32/.pyenv/versions/3.11.9/envs/note/lib/python3.11/site-packages/airflow/operators/python.py", line 235, in execute
    return_value = self.execute_callable()
                   ^^^^^^^^^^^^^^^^^^^^^^^
  File "/Users/DE32/.pyenv/versions/3.11.9/envs/note/lib/python3.11/site-packages/airflow/operators/python.py", line 757, in execute_callable
    self._prepare_venv(tmp_path)
  File "/Users/DE32/.pyenv/versions/3.11.9/envs/note/lib/python3.11/site-packages/airflow/operators/python.py", line 669, in _prepare_venv
    prepare_virtualenv(
  File "/Users/DE32/.pyenv/versions/3.11.9/envs/note/lib/python3.11/site-packages/airflow/utils/python_virtualenv.py", line 119, in prepare_virtualenv
    execute_in_subprocess(pip_cmd)
  File "/Users/DE32/.pyenv/versions/3.11.9/envs/note/lib/python3.11/site-packages/airflow/utils/process_utils.py", line 172, in execute_in_subprocess
    execute_in_subprocess_with_kwargs(cmd, cwd=cwd)
  File "/Users/DE32/.pyenv/versions/3.11.9/envs/note/lib/python3.11/site-packages/airflow/utils/process_utils.py", line 195, in execute_in_subprocess_with_kwargs
    raise subprocess.CalledProcessError(exit_code, cmd)
subprocess.CalledProcessError: Command '['/var/folders/qv/0knwm5h50ml0skpppwpbks_r0000gp/T/venvg0_4ucjm/bin/pip', 'install', '-r', '/var/folders/qv/0knwm5h50ml0skpppwpbks_r0000gp/T/venvg0_4ucjm/requirements.txt']' returned non-zero exit status 1.
[2024-07-30T10:29:23.879+0900] {taskinstance.py:1206} INFO - Marking task as FAILED. dag_id=movie, task_id=get_data, run_id=scheduled__2024-07-28T04:10:00+00:00, execution_date=20240728T041000, start_date=20240730T012922, end_date=20240730T012923
[2024-07-30T10:29:23.883+0900] {standard_task_runner.py:110} ERROR - Failed to execute job 624 for task get_data (Command '['/var/folders/qv/0knwm5h50ml0skpppwpbks_r0000gp/T/venvg0_4ucjm/bin/pip', 'install', '-r', '/var/folders/qv/0knwm5h50ml0skpppwpbks_r0000gp/T/venvg0_4ucjm/requirements.txt']' returned non-zero exit status 1.; 4417)
[2024-07-30T10:29:23.928+0900] {local_task_job_runner.py:243} INFO - Task exited with return code 1
[2024-07-30T10:29:23.975+0900] {taskinstance.py:3503} INFO - 0 downstream tasks scheduled from follow-on schedule check
[2024-07-30T10:29:23.976+0900] {local_task_job_runner.py:222} INFO - ::endgroup::
